<?xml version="1.0"?>
<robot name="simple_bot">

 <material name="black">
   <color rgba="0 0 0 1"/>
  </material>
  <material name="white">
    <color rgba="1 1 1 1"/>
  </material>

<link name="body">
    <visual>
      <geometry>
        <box size="0.4 0.2 0.1"/>
      </geometry>
      <material name="white"/>
    </visual>
    <collision>
      <geometry>
        <box size="0.4 0.2 0.1"/>
      </geometry>
    </collision>
    <inertial>
      <mass value="10"/>
      <inertia ixx="0.4" ixy="0.0" ixz="0.0" iyy="0.4" iyz="0.0" izz="0.2"/>
    </inertial>
  </link>

  <gazebo reference="base_link">
      <material>Gazebo/White</material>
  </gazebo>

<link name="right_front_wheel">
  <!--origin xyz="0.1 -0.13 0.1" rpy="0 1.5707 1.5707"/-->
    <visual>
      <origin rpy="0 1.5707 1.5707" xyz="0 0 0"/>
      <geometry>
        <cylinder length="0.1" radius="0.05"/>
      </geometry>
      <material name="black"/>
    </visual>
     <collision>
      <origin rpy="0 1.5707 1.5707" xyz="0 0 0"/>
      <geometry>
        <cylinder length="0.1" radius="0.05"/>
      </geometry>
      <material name="black"/>
    </collision>
     <inertial>
      <origin xyz="0 0 0" rpy="0 1.5707 1.5707"/>
      <mass value="5"/>
      <inertia
        ixx="1.0" ixy="0.0" ixz="0.0"
        iyy="1.0" iyz="0.0"
        izz="1.0"/>
    </inertial>
  </link>

  <gazebo reference="right_front_wheel">
      <material>Gazebo/Black</material>
  </gazebo>

<joint name="right_front_wheel_joint" type="continuous">
    <parent link="body"/>
    <child link="right_front_wheel"/>
    <origin rpy="0 0 0" xyz="0.1 -0.15 0"/>
    <axis xyz="0 1 0" rpy="0 0 0"/>
    <limit effort="100" velocity="100"/>
    <joint_properties damping="1.0" friction="1.0"/> 
  </joint>



<link name="left_front_wheel">
  <!--origin xyz="0.1 0.13 0.1" rpy="0 1.5707 1.5707"/-->
    <visual>
      <origin rpy="0 1.5707 1.5707" xyz="0 0 0"/>
      <geometry>
        <cylinder length="0.1" radius="0.05"/>
      </geometry>
      <material name="black"/>
    </visual>
     <collision>
      <origin rpy="0 1.5707 1.5707" xyz="0 0 0"/>
      <geometry>
        <cylinder length="0.1" radius="0.05"/>
      </geometry>
      <material name="black"/>
    </collision>
     <inertial>
      <origin xyz="0 0 0" rpy="0 1.5707 1.5707"/>
      <mass value="5"/>
      <inertia
        ixx="1.0" ixy="0.0" ixz="0.0"
        iyy="1.0" iyz="0.0"
        izz="1.0"/>
    </inertial>
  </link>

  <gazebo reference="left_front_wheel">
      <material>Gazebo/Black</material>
  </gazebo>

<joint name="left_front_wheel_joint" type="continuous">
    <parent link="body"/>
    <child link="left_front_wheel"/>
    <origin rpy="0 0 0" xyz="0.1 0.15 0"/>
    <axis xyz="0 1 0" rpy="0 0 0"/>
    <limit effort="100" velocity="100"/>
    <joint_properties damping="1.0" friction="1.0"/> 
  </joint>


<link name="right_rear_wheel">
  <!--origin xyz="-0.1 -0.13 0.1" rpy="0 1.5707 1.5707"/-->
    <visual>
      <origin rpy="0 1.5707 1.5707" xyz="0 0 0"/>
      <geometry>
        <cylinder length="0.1" radius="0.05"/>
      </geometry>
      <material name="black"/>
    </visual>
     <collision>
      <origin rpy="0 1.5707 1.5707" xyz="0 0 0"/>
      <geometry>
        <cylinder length="0.1" radius="0.05"/>
      </geometry>
      <material name="black"/>
    </collision>
     <inertial>
      <origin xyz="0 0 0" rpy="0 1.5707 1.5707"/>
      <mass value="5"/>
      <inertia
        ixx="1.0" ixy="0.0" ixz="0.0"
        iyy="1.0" iyz="0.0"
        izz="1.0"/>
    </inertial>
  </link>

  <gazebo reference="right_rear_wheel">
      <material>Gazebo/Black</material>
  </gazebo>

<joint name="right_rear_wheel_joint" type="continuous">
    <parent link="body"/>
    <child link="right_rear_wheel"/>
    <origin rpy="0 0 0" xyz="-0.1 -0.15 0"/>
    <axis xyz="0 1 0" rpy="0 0 0"/>
    <limit effort="100" velocity="100"/>
    <joint_properties damping="1.0" friction="1.0"/>
  </joint>



<link name="left_rear_wheel">
  <!--origin xyz="-0.1 0.13 0.1" rpy="0 1.5707 1.5707"/-->
    <visual>
      <origin rpy="0 1.5707 1.5707" xyz="0 0 0"/>
      <geometry>
        <cylinder length="0.1" radius="0.05"/>
      </geometry>
      <material name="black"/>
    </visual>
     <collision>
      <origin rpy="0 1.5707 1.5707" xyz="0 0 0"/>
      <geometry>
        <cylinder length="0.1" radius="0.05"/>
      </geometry>
      <material name="black"/>
    </collision>
     <inertial>
      <origin xyz="0 0 0" rpy="0 1.5707 1.5707"/>
      <mass value="5"/>
      <inertia
        ixx="1.0" ixy="0.0" ixz="0.0"
        iyy="1.0" iyz="0.0"
        izz="1.0"/>
    </inertial>
  </link>
  
  <gazebo reference="left_rear_wheel">
      <material>Gazebo/Black</material>
  </gazebo>

<joint name="left_rear_wheel_joint" type="continuous">
    <parent link="body"/>
    <child link="left_rear_wheel"/>
    <origin rpy="0 0 0" xyz="-0.1 0.15 0"/>
    <axis xyz="0 1 0" rpy="0 0 0"/>
    <limit effort="100" velocity="100"/>
    <joint_properties damping="1.0" friction="1.0"/>
  </joint>

  
  <gazebo>
    <plugin name="differential_drive_controller" filename="libgazebo_ros_diff_drive.so">
      <legacyMode>false</legacyMode>
      <alwaysOn>true</alwaysOn>
      <updateRate>20</updateRate>
      <leftFrontJoint>left_front_wheel_joint</leftFrontJoint>
      <rightFrontJoint>right_front_wheel_joint</rightFrontJoint>
      <leftRearJoint>left_rear_wheel_joint</leftRearJoint>
      <rightRearJoint>right_rear_wheel_joint</rightRearJoint>
      <wheelSeparation>0.4</wheelSeparation>
      <wheelDiameter>0.1</wheelDiameter>
      <torque>20</torque>
      <commandTopic>cmd_vel</commandTopic>
      <odometryTopic>odom</odometryTopic>
      <odometryFrame>odom</odometryFrame>
      <robotBaseFrame>body</robotBaseFrame>
    </plugin>
  </gazebo>

  <gazebo reference="body">
    </gazebo>



</robot>